Workbook
Name Population_ancre: 'Réglages'!$D$9
Name Prix_ancre: 'Réglages'!$D$10
Name Exposant: 'Réglages'!$D$11
Name Population_minimum: 'Réglages'!$D$12
Name Population_maximum: 'Réglages'!$D$13
Name Poids_carte: 'Réglages'!$D$17
Name Poids_travaux: 'Réglages'!$D$18
Name Poids_chantiers: 'Réglages'!$D$19
Name Poids_participer: 'Réglages'!$D$20
Name Poids_diagnostic: 'Réglages'!$D$21
Name Chantiers_demi_poids_sous: 'Réglages'!$D$25
Name Chantiers_plein_poids_des: 'Réglages'!$D$26
Name Remise_par_module_ajoute: 'Réglages'!$D$30
Name Remise_engagement_1: 'Réglages'!$D$31
Name Remise_engagement_2: 'Réglages'!$D$32
Name Remise_engagement_3: 'Réglages'!$D$33
Name Remise_engagement_4: 'Réglages'!$D$34
Name Table_engagements: 'Réglages'!$A$31:$D$34
Name Mise_en_service_mois: 'Réglages'!$D$38
Name Mise_en_service_offerte_sous: 'Réglages'!$D$39
Name Fourchette_marge: 'Réglages'!$D$43
Name Seuil_1: 'Réglages'!$D$47
Name Seuil_2: 'Réglages'!$D$48
Name Seuil_3: 'Réglages'!$D$49

Sheet Tableau de bord
B2: Simulateur de tarification Open Projets
B3: Réglez la commune dans les cases jaunes : tout le tableau de bord suit. Les montants sont hors taxes.
B5: Votre scénario | E5: Le prix pour cette commune
B6: Collectivité | C6: Ville de Trifouillis | E6: ABONNEMENT MENSUEL HT | F6: ABONNEMENT ANNUEL HT | G6: MISE EN SERVICE | H6: TOTAL SUR LA DURÉE
B7: Habitants | C7: 12000 | E7: =Calculs!R4 | F7: =Calculs!S4 | G7: =Calculs!T4 | H7: =Calculs!U4
B8: Carte des projets urbains | C8: Oui | E8: =TEXT(Calculs!L4,"0")&IF(Calculs!L4>1," modules, "," module, ")&TEXT('Tableau de bord'!$C$13,"0")&IF('Tableau de bord'!$C$13>1," ans"," an") | F8: Chaque année de l'engagement | G8: Une seule fois, la première année | H8: Mise en service comprise, hors taxes
B9: Travaux du quotidien | C9: Oui
B10: Chantiers et arrêtés | C10: Non | E10: CE QUE LE VISITEUR VOIT SUR LE SITE | G10: COMMANDE PUBLIQUE
B11: Signalement | C11: Non | E11: ="de "&TRIM(TEXT(Calculs!X4,"# ##0"))&" à "&TRIM(TEXT(Calculs!Y4,"# ##0"))&" € par mois" | G11: =Calculs!V4
B12: Diagnostic terrain | C12: Non | E12: La fourchette publique, le tarif exact se demande | G12: =IF(Calculs!V4="Sous les seuils","Commande sans mise en concurrence possible","Le total dépasse "&TRIM(TEXT(IF(Calculs!U4>=Seuil_3,Seuil_3,IF(Calculs!U4>=Seuil_2,Seuil_2,Seuil_1)),"# ##0"))&" € HT")
B13: Engagement, en années | C13: 3
E14: Le détail du prix, par mois
E15: Poste | F15: Montant
B16: Réglages modifiés par rapport au site | C16: =COUNTIF('Réglages'!$E$1:$E$51,"modifié") | E16: Carte des projets urbains | F16: =IF(Calculs!F4=0,"non retenu",Calculs!F4)
B17: Zéro veut dire que ce classeur applique exactement la grille en production. Les réglages sont dans la feuille du même nom. | E17: Travaux du quotidien | F17: =IF(Calculs!G4=0,"non retenu",Calculs!G4)
E18: Chantiers et arrêtés | F18: =IF(Calculs!H4=0,"non retenu",Calculs!H4)
E19: Signalement | F19: =IF(Calculs!I4=0,"non retenu",Calculs!I4)
E20: Diagnostic terrain | F20: =IF(Calculs!J4=0,"non retenu",Calculs!J4)
E21: Remise multi-modules, sur le plus cher | F21: =IF(Calculs!N4=0,"aucune",-Calculs!N4)
E22: Remise d'engagement | F22: =IF(Calculs!Q4=0,"aucune",-Calculs!Q4)
E23: Abonnement mensuel HT | F23: =Calculs!R4
B68: Les scénarios vides de la feuille Scénarios apparaissent sans barre. Les seuils de la commande publique sont à 60 000, 90 000 et 216 000 euros hors taxes sur toute la durée.

Sheet Lisez-moi
B2: Comment se servir de ce classeur
B5: Ce classeur reproduit le calcul de prix de la page de tarification du site, tel qu'il est en production. Il sert à préparer un rendez-vous, à comparer des offres et à voir ce que donnerait un changement de grille. Rien n'est à renvoyer : c'est votre outil de travail.
B7: Les cases jaunes se remplissent, tout le reste se calcule. La feuille Tableau de bord affiche le prix d'une commune : sa population, les modules retenus, la durée d'engagement, puis l'abonnement, la mise en service, le total sur la durée, la fourchette que le visiteur voit sur le site et la situation face aux seuils de la commande publique. Les graphiques suivent le scénario.
B9: La feuille Scénarios accepte jusqu'à vingt-cinq cas, un par ligne, avec le prix de chacun et sa fourchette publique. Le dernier graphique du tableau de bord les compare.
B11: La feuille Grille montre le prix sur toutes les tailles de communes, module par module puis pour la suite complète. C'est elle qui nourrit la courbe du tableau de bord.
B13: La feuille Réglages contient la grille de production et la valeur que ce classeur utilise. Vous pouvez modifier cette dernière pour voir ce qu'un autre prix, un autre poids ou une autre remise donnerait. Le tableau de bord compte les réglages modifiés : à zéro, vous êtes exactement sur la grille du site. Pour revenir en arrière, recopiez la valeur grise.
B15: Les feuilles sont protégées sans mot de passe, pour éviter d'effacer une formule par mégarde. L'onglet Révision d'Excel permet d'ôter la protection si vous voulez aller plus loin. Les colonnes de calcul détaillé sont repliées à droite des feuilles Grille et Scénarios.
B17: Tous les montants sont hors taxes. La TVA de 20 % s'ajoute.
B19: Case jaune : à remplir par vous
B20: Case grise : la valeur en production sur le site, en lecture seule

Sheet Réglages
B2: Les réglages de la grille
B3: La colonne grise est la grille en production sur le site. La colonne jaune est celle que tout le classeur utilise : elle part de la production, et vous pouvez la modifier pour voir ce que cela change. Pour revenir à la grille du site, recopiez la valeur grise.
B6: La courbe
B7: Le prix d'une unité de poids suit la population en puissance. Deux chiffres suffisent : le prix à l'ancre et l'exposant. Avec un exposant de 0,5, une commune dix fois plus peuplée paie un peu plus de trois fois plus.
B8: Réglage | C8: Sur le site | D8: Utilisé ici | E8: Écart | F8: Ce que cela veut dire
B9: Population de l'ancre | C9: 12000 | D9: 12000 | E9: =IF(D9=C9,"","modifié") | F9: La commune de référence de la courbe
B10: Prix mensuel HT d'une unité de poids à l'ancre | C10: 200 | D10: 200 | E10: =IF(D10=C10,"","modifié") | F10: Le prix du module Carte pour cette commune
B11: Exposant de la courbe | C11: 0.5 | D11: 0.5 | E11: =IF(D11=C11,"","modifié") | F11: Plus il est haut, plus les grandes villes paient
B12: Population minimale | C12: 500 | D12: 500 | E12: =IF(D12=C12,"","modifié") | F12: En dessous, la page ramène à ce plancher
B13: Population maximale | C13: 2500000 | D13: 2500000 | E13: =IF(D13=C13,"","modifié") | F13: Au-dessus, la page ramène à ce plafond
B14: Le poids de chaque module
B15: Le prix d'un module est le prix de l'unité multiplié par son poids.
B16: Réglage | C16: Sur le site | D16: Utilisé ici | E16: Écart | F16: Ce que cela veut dire
B17: Carte des projets urbains | C17: 1 | D17: 1 | E17: =IF(D17=C17,"","modifié")
B18: Travaux du quotidien | C18: 0.6 | D18: 0.6 | E18: =IF(D18=C18,"","modifié")
B19: Chantiers et arrêtés | C19: 3 | D19: 3 | E19: =IF(D19=C19,"","modifié")
B20: Signalement | C20: 2 | D20: 2 | E20: =IF(D20=C20,"","modifié")
B21: Diagnostic terrain | C21: 0.8 | D21: 0.8 | E21: =IF(D21=C21,"","modifié")
B22: Le module Chantiers et arrêtés dans les petites communes
B23: Il vaut la moitié de son poids jusqu'au premier seuil, son poids entier à partir du second, et monte en pente douce entre les deux.
B24: Réglage | C24: Sur le site | D24: Utilisé ici | E24: Écart | F24: Ce que cela veut dire
B25: Demi-poids jusqu'à | C25: 5000 | D25: 5000 | E25: =IF(D25=C25,"","modifié") | F25: habitants
B26: Poids entier à partir de | C26: 20000 | D26: 20000 | E26: =IF(D26=C26,"","modifié") | F26: habitants
B27: Les remises
B28: Prendre plusieurs modules fait baisser le plus cher d'entre eux, de ce taux par module ajouté au premier. L'engagement baisse ensuite tout l'abonnement, chaque année.
B29: Réglage | C29: Sur le site | D29: Utilisé ici | E29: Écart | F29: Ce que cela veut dire
B30: Remise par module ajouté, sur le module le plus cher | C30: 0.1 | D30: 0.1 | E30: =IF(D30=C30,"","modifié") | F30: Deux modules : ce taux, trois : le double, et ainsi de suite
A31: 1 | B31: Engagement 1 an | C31: 0 | D31: 0 | E31: =IF(D31=C31,"","modifié") | F31: Remise sur l'abonnement, chaque année
A32: 2 | B32: Engagement 2 ans | C32: 0.1 | D32: 0.1 | E32: =IF(D32=C32,"","modifié") | F32: Remise sur l'abonnement, chaque année
A33: 3 | B33: Engagement 3 ans | C33: 0.15 | D33: 0.15 | E33: =IF(D33=C33,"","modifié") | F33: Remise sur l'abonnement, chaque année
A34: 4 | B34: Engagement 4 ans | C34: 0.2 | D34: 0.2 | E34: =IF(D34=C34,"","modifié") | F34: Remise sur l'abonnement, chaque année
B35: La mise en service
B36: Facturée une seule fois, la première année, en mois d'abonnement au tarif obtenu. Un seuil d'habitants à zéro veut dire qu'elle n'est jamais offerte.
B37: Réglage | C37: Sur le site | D37: Utilisé ici | E37: Écart | F37: Ce que cela veut dire
B38: Mise en service, en mois d'abonnement | C38: 6 | D38: 6 | E38: =IF(D38=C38,"","modifié")
B39: Mise en service offerte sous | C39: 0 | D39: 0 | E39: =IF(D39=C39,"","modifié") | F39: habitants, zéro = jamais offerte
B40: La fourchette affichée au public
B41: Un visiteur du site ne voit pas le prix exact : une fourchette autour du prix, à plus ou moins cette marge, arrondie vers l'extérieur (à la dizaine sous 1 000 euros, à la centaine sous 10 000, au millier sous 100 000, à la dizaine de milliers au-delà). Vous voyez les deux dans ce classeur.
B42: Réglage | C42: Sur le site | D42: Utilisé ici | E42: Écart | F42: Ce que cela veut dire
B43: Marge de la fourchette | C43: 0.2 | D43: 0.2 | E43: =IF(D43=C43,"","modifié") | F43: De part et d'autre du prix exact
...

Sheet Grille
B2: La grille sur toutes les tailles de communes
B3: Prix mensuels hors taxes, avec la durée d'engagement choisie ci-dessous : chaque module pris seul, puis la suite complète des cinq modules avec sa remise multi-modules. Les populations se modifient.
B5: Durée d'engagement appliquée à cette grille, en années | C5: 1
B7: Habitants | C7: Une unité de poids | D7: Carte des projets urbains seul | E7: Travaux du quotidien seul | F7: Chantiers et arrêtés seul | G7: Signalement seul | H7: Diagnostic terrain seul | I7: Les 5 modules, par mois | J7: Mise en service | K7: Total sur la durée | L7: Seuil dépassé | M7: Fourchette publique, par mois | P7: Population retenue | Q7: Prix d'une unité de poids | R7: Poids chantiers | S7: Prix Carte des projets urbains | T7: Prix Travaux du quotidien | U7: Prix Chantiers et arrêtés | V7: Prix Signalement | W7: Prix Diagnostic terrain | X7: Total avant remises | Y7: Modules retenus | Z7: Taux remise multi-modules | AA7: Remise multi-modules | AB7: Après remise multi-modules | AC7: Taux engagement | AD7: Remise engagement | AE7: Mensuel | AF7: Annuel | AG7: Mise en service | AH7: Total sur la durée | AI7: Seuil | AJ7: Pas d'arrondi (mensuel) | AK7: Fourchette basse (mensuel) | AL7: Fourchette haute (mensuel) | AM7: Pas d'arrondi (total) | AN7: Fourchette basse (total) | AO7: Fourchette haute (total)
B8: 500 | C8: =Q8 | D8: =S8*(1-AC8) | E8: =T8*(1-AC8) | F8: =U8*(1-AC8) | G8: =V8*(1-AC8) | H8: =W8*(1-AC8) | I8: =AE8 | J8: =AG8 | K8: =AH8 | L8: =AI8 | M8: =TRIM(TEXT(AK8,"# ##0"))&" à "&TRIM(TEXT(AL8,"# ##0"))&" €" | P8: =MIN(Population_maximum,MAX(Population_minimum,ROUND($B8,0))) | Q8: =Prix_ancre*(P8/Population_ancre)^Exposant | R8: =IF(P8<=Chantiers_demi_poids_sous,Poids_chantiers/2,IF(P8>=Chantiers_plein_poids_des,Poids_chantiers,Poids_chantiers*(0.5+0.5*(LN(P8)-LN(Chantiers_demi_poids_sous))/(LN(Chantiers_plein_poids_des)-LN(Chantiers_demi_poids_sous))))) | S8: =Q8*Poids_carte | T8: =Q8*Poids_travaux | U8: =Q8*R8 | V8: =Q8*Poids_participer | W8: =Q8*Poids_diagnostic | X8: =SUM(S8:W8) | Y8: =5 | Z8: =MIN(0.9,MAX(0,Y8-1)*Remise_par_module_ajoute) | AA8: =MAX(S8:W8)*Z8 | AB8: =X8-AA8 | AC8: =IFERROR(VLOOKUP('Grille'!$C$5,Table_engagements,4,FALSE),0) | AD8: =AB8*AC8 | AE8: =AB8-AD8 | AF8: =AE8*12 | AG8: =IF(P8<Mise_en_service_offerte_sous,0,AE8*Mise_en_service_mois) | AH8: =AG8+AF8*IF(N('Grille'!$C$5)>0,'Grille'!$C$5,1) | AI8: =IF(AH8>=Seuil_3,"Procédure formalisée",IF(AH8>=Seuil_2,"Publicité obligatoire",IF(AH8>=Seuil_1,"Procédure adaptée","Sous les seuils"))) | AJ8: =IF(AE8<1000,10,IF(AE8<10000,100,IF(AE8<100000,1000,10000))) | AK8: =FLOOR(AE8*(1-Fourchette_marge),AJ8) | AL8: =CEILING(AE8*(1+Fourchette_marge),AJ8) | AM8: =IF(AH8<1000,10,IF(AH8<10000,100,IF(AH8<100000,1000,10000))) | AN8: =FLOOR(AH8*(1-Fourchette_marge),AM8) | AO8: =CEILING(AH8*(1+Fourchette_marge),AM8)
B9: 800 | C9: =Q9 | D9: =S9*(1-AC9) | E9: =T9*(1-AC9) | F9: =U9*(1-AC9) | G9: =V9*(1-AC9) | H9: =W9*(1-AC9) | I9: =AE9 | J9: =AG9 | K9: =AH9 | L9: =AI9 | M9: =TRIM(TEXT(AK9,"# ##0"))&" à "&TRIM(TEXT(AL9,"# ##0"))&" €" | P9: =MIN(Population_maximum,MAX(Population_minimum,ROUND($B9,0))) | Q9: =Prix_ancre*(P9/Population_ancre)^Exposant | R9: =IF(P9<=Chantiers_demi_poids_sous,Poids_chantiers/2,IF(P9>=Chantiers_plein_poids_des,Poids_chantiers,Poids_chantiers*(0.5+0.5*(LN(P9)-LN(Chantiers_demi_poids_sous))/(LN(Chantiers_plein_poids_des)-LN(Chantiers_demi_poids_sous))))) | S9: =Q9*Poids_carte | T9: =Q9*Poids_travaux | U9: =Q9*R9 | V9: =Q9*Poids_participer | W9: =Q9*Poids_diagnostic | X9: =SUM(S9:W9) | Y9: =5 | Z9: =MIN(0.9,MAX(0,Y9-1)*Remise_par_module_ajoute) | AA9: =MAX(S9:W9)*Z9 | AB9: =X9-AA9 | AC9: =IFERROR(VLOOKUP('Grille'!$C$5,Table_engagements,4,FALSE),0) | AD9: =AB9*AC9 | AE9: =AB9-AD9 | AF9: =AE9*12 | AG9: =IF(P9<Mise_en_service_offerte_sous,0,AE9*Mise_en_service_mois) | AH9: =AG9+AF9*IF(N('Grille'!$C$5)>0,'Grille'!$C$5,1) | AI9: =IF(AH9>=Seuil_3,"Procédure formalisée",IF(AH9>=Seuil_2,"Publicité obligatoire",IF(AH9>=Seuil_1,"Procédure adaptée","Sous les seuils"))) | AJ9: =IF(AE9<1000,10,IF(AE9<10000,100,IF(AE9<100000,1000,10000))) | AK9: =FLOOR(AE9*(1-Fourchette_marge),AJ9) | AL9: =CEILING(AE9*(1+Fourchette_marge),AJ9) | AM9: =IF(AH9<1000,10,IF(AH9<10000,100,IF(AH9<100000,1000,10000))) | AN9: =FLOOR(AH9*(1-Fourchette_marge),AM9) | AO9: =CEILING(AH9*(1+Fourchette_marge),AM9)
B10: 1500 | C10: =Q10 | D10: =S10*(1-AC10) | E10: =T10*(1-AC10) | F10: =U10*(1-AC10) | G10: =V10*(1-AC10) | H10: =W10*(1-AC10) | I10: =AE10 | J10: =AG10 | K10: =AH10 | L10: =AI10 | M10: =TRIM(TEXT(AK10,"# ##0"))&" à "&TRIM(TEXT(AL10,"# ##0"))&" €" | P10: =MIN(Population_maximum,MAX(Population_minimum,ROUND($B10,0))) | Q10: =Prix_ancre*(P10/Population_ancre)^Exposant | R10: =IF(P10<=Chantiers_demi_poids_sous,Poids_chantiers/2,IF(P10>=Chantiers_plein_poids_des,Poids_chantiers,Poids_chantiers*(0.5+0.5*(LN(P10)-LN(Chantiers_demi_poids_sous))/(LN(Chantiers_plein_poids_des)-LN(Chantiers_demi_poids_sous))))) | S10: =Q10*Poids_carte | T10: =Q10*Poids_travaux | U10: =Q10*R10 | V10: =Q10*Poids_participer | W10: =Q10*Poids_diagnostic | X10: =SUM(S10:W10) | Y10: =5 | Z10: =MIN(0.9,MAX(0,Y10-1)*Remise_par_module_ajoute) | AA10: =MAX(S10:W10)*Z10 | AB10: =X10-AA10 | AC10: =IFERROR(VLOOKUP('Grille'!$C$5,Table_engagements,4,FALSE),0) | AD10: =AB10*AC10 | AE10: =AB10-AD10 | AF10: =AE10*12 | AG10: =IF(P10<Mise_en_service_offerte_sous,0,AE10*Mise_en_service_mois) | AH10: =AG10+AF10*IF(N('Grille'!$C$5)>0,'Grille'!$C$5,1) | AI10: =IF(AH10>=Seuil_3,"Procédure formalisée",IF(AH10>=Seuil_2,"Publicité obligatoire",IF(AH10>=Seuil_1,"Procédure adaptée","Sous les seuils"))) | AJ10: =IF(AE10<1000,10,IF(AE10<10000,100,IF(AE10<100000,1000,10000))) | AK10: =FLOOR(AE10*(1-Fourchette_marge),AJ10) | AL10: =CEILING(AE10*(1+Fourchette_marge),AJ10) | AM10: =IF(AH10<1000,10,IF(AH10<10000,100,IF(AH10<100000,1000,10000))) | AN10: =FLOOR(AH10*(1-Fourchette_marge),AM10) | AO10: =CEILING(AH10*(1+Fourchette_marge),AM10)
B11: 3000 | C11: =Q11 | D11: =S11*(1-AC11) | E11: =T11*(1-AC11) | F11: =U11*(1-AC11) | G11: =V11*(1-AC11) | H11: =W11*(1-AC11) | I11: =AE11 | J11: =AG11 | K11: =AH11 | L11: =AI11 | M11: =TRIM(TEXT(AK11,"# ##0"))&" à "&TRIM(TEXT(AL11,"# ##0"))&" €" | P11: =MIN(Population_maximum,MAX(Population_minimum,ROUND($B11,0))) | Q11: =Prix_ancre*(P11/Population_ancre)^Exposant | R11: =IF(P11<=Chantiers_demi_poids_sous,Poids_chantiers/2,IF(P11>=Chantiers_plein_poids_des,Poids_chantiers,Poids_chantiers*(0.5+0.5*(LN(P11)-LN(Chantiers_demi_poids_sous))/(LN(Chantiers_plein_poids_des)-LN(Chantiers_demi_poids_sous))))) | S11: =Q11*Poids_carte | T11: =Q11*Poids_travaux | U11: =Q11*R11 | V11: =Q11*Poids_participer | W11: =Q11*Poids_diagnostic | X11: =SUM(S11:W11) | Y11: =5 | Z11: =MIN(0.9,MAX(0,Y11-1)*Remise_par_module_ajoute) | AA11: =MAX(S11:W11)*Z11 | AB11: =X11-AA11 | AC11: =IFERROR(VLOOKUP('Grille'!$C$5,Table_engagements,4,FALSE),0) | AD11: =AB11*AC11 | AE11: =AB11-AD11 | AF11: =AE11*12 | AG11: =IF(P11<Mise_en_service_offerte_sous,0,AE11*Mise_en_service_mois) | AH11: =AG11+AF11*IF(N('Grille'!$C$5)>0,'Grille'!$C$5,1) | AI11: =IF(AH11>=Seuil_3,"Procédure formalisée",IF(AH11>=Seuil_2,"Publicité obligatoire",IF(AH11>=Seuil_1,"Procédure adaptée","Sous les seuils"))) | AJ11: =IF(AE11<1000,10,IF(AE11<10000,100,IF(AE11<100000,1000,10000))) | AK11: =FLOOR(AE11*(1-Fourchette_marge),AJ11) | AL11: =CEILING(AE11*(1+Fourchette_marge),AJ11) | AM11: =IF(AH11<1000,10,IF(AH11<10000,100,IF(AH11<100000,1000,10000))) | AN11: =FLOOR(AH11*(1-Fourchette_marge),AM11) | AO11: =CEILING(AH11*(1+Fourchette_marge),AM11)
B12: 5000 | C12: =Q12 | D12: =S12*(1-AC12) | E12: =T12*(1-AC12) | F12: =U12*(1-AC12) | G12: =V12*(1-AC12) | H12: =W12*(1-AC12) | I12: =AE12 | J12: =AG12 | K12: =AH12 | L12: =AI12 | M12: =TRIM(TEXT(AK12,"# ##0"))&" à "&TRIM(TEXT(AL12,"# ##0"))&" €" | P12: =MIN(Population_maximum,MAX(Population_minimum,ROUND($B12,0))) | Q12: =Prix_ancre*(P12/Population_ancre)^Exposant | R12: =IF(P12<=Chantiers_demi_poids_sous,Poids_chantiers/2,IF(P12>=Chantiers_plein_poids_des,Poids_chantiers,Poids_chantiers*(0.5+0.5*(LN(P12)-LN(Chantiers_demi_poids_sous))/(LN(Chantiers_plein_poids_des)-LN(Chantiers_demi_poids_sous))))) | S12: =Q12*Poids_carte | T12: =Q12*Poids_travaux | U12: =Q12*R12 | V12: =Q12*Poids_participer | W12: =Q12*Poids_diagnostic | X12: =SUM(S12:W12) | Y12: =5 | Z12: =MIN(0.9,MAX(0,Y12-1)*Remise_par_module_ajoute) | AA12: =MAX(S12:W12)*Z12 | AB12: =X12-AA12 | AC12: =IFERROR(VLOOKUP('Grille'!$C$5,Table_engagements,4,FALSE),0) | AD12: =AB12*AC12 | AE12: =AB12-AD12 | AF12: =AE12*12 | AG12: =IF(P12<Mise_en_service_offerte_sous,0,AE12*Mise_en_service_mois) | AH12: =AG12+AF12*IF(N('Grille'!$C$5)>0,'Grille'!$C$5,1) | AI12: =IF(AH12>=Seuil_3,"Procédure formalisée",IF(AH12>=Seuil_2,"Publicité obligatoire",IF(AH12>=Seuil_1,"Procédure adaptée","Sous les seuils"))) | AJ12: =IF(AE12<1000,10,IF(AE12<10000,100,IF(AE12<100000,1000,10000))) | AK12: =FLOOR(AE12*(1-Fourchette_marge),AJ12) | AL12: =CEILING(AE12*(1+Fourchette_marge),AJ12) | AM12: =IF(AH12<1000,10,IF(AH12<10000,100,IF(AH12<100000,1000,10000))) | AN12: =FLOOR(AH12*(1-Fourchette_marge),AM12) | AO12: =CEILING(AH12*(1+Fourchette_marge),AM12)
B13: 8000 | C13: =Q13 | D13: =S13*(1-AC13) | E13: =T13*(1-AC13) | F13: =U13*(1-AC13) | G13: =V13*(1-AC13) | H13: =W13*(1-AC13) | I13: =AE13 | J13: =AG13 | K13: =AH13 | L13: =AI13 | M13: =TRIM(TEXT(AK13,"# ##0"))&" à "&TRIM(TEXT(AL13,"# ##0"))&" €" | P13: =MIN(Population_maximum,MAX(Population_minimum,ROUND($B13,0))) | Q13: =Prix_ancre*(P13/Population_ancre)^Exposant | R13: =IF(P13<=Chantiers_demi_poids_sous,Poids_chantiers/2,IF(P13>=Chantiers_plein_poids_des,Poids_chantiers,Poids_chantiers*(0.5+0.5*(LN(P13)-LN(Chantiers_demi_poids_sous))/(LN(Chantiers_plein_poids_des)-LN(Chantiers_demi_poids_sous))))) | S13: =Q13*Poids_carte | T13: =Q13*Poids_travaux | U13: =Q13*R13 | V13: =Q13*Poids_participer | W13: =Q13*Poids_diagnostic | X13: =SUM(S13:W13) | Y13: =5 | Z13: =MIN(0.9,MAX(0,Y13-1)*Remise_par_module_ajoute) | AA13: =MAX(S13:W13)*Z13 | AB13: =X13-AA13 | AC13: =IFERROR(VLOOKUP('Grille'!$C$5,Table_engagements,4,FALSE),0) | AD13: =AB13*AC13 | AE13: =AB13-AD13 | AF13: =AE13*12 | AG13: =IF(P13<Mise_en_service_offerte_sous,0,AE13*Mise_en_service_mois) | AH13: =AG13+AF13*IF(N('Grille'!$C$5)>0,'Grille'!$C$5,1) | AI13: =IF(AH13>=Seuil_3,"Procédure formalisée",IF(AH13>=Seuil_2,"Publicité obligatoire",IF(AH13>=Seuil_1,"Procédure adaptée","Sous les seuils"))) | AJ13: =IF(AE13<1000,10,IF(AE13<10000,100,IF(AE13<100000,1000,10000))) | AK13: =FLOOR(AE13*(1-Fourchette_marge),AJ13) | AL13: =CEILING(AE13*(1+Fourchette_marge),AJ13) | AM13: =IF(AH13<1000,10,IF(AH13<10000,100,IF(AH13<100000,1000,10000))) | AN13: =FLOOR(AH13*(1-Fourchette_marge),AM13) | AO13: =CEILING(AH13*(1+Fourchette_marge),AM13)
B14: 12000 | C14: =Q14 | D14: =S14*(1-AC14) | E14: =T14*(1-AC14) | F14: =U14*(1-AC14) | G14: =V14*(1-AC14) | H14: =W14*(1-AC14) | I14: =AE14 | J14: =AG14 | K14: =AH14 | L14: =AI14 | M14: =TRIM(TEXT(AK14,"# ##0"))&" à "&TRIM(TEXT(AL14,"# ##0"))&" €" | P14: =MIN(Population_maximum,MAX(Population_minimum,ROUND($B14,0))) | Q14: =Prix_ancre*(P14/Population_ancre)^Exposant | R14: =IF(P14<=Chantiers_demi_poids_sous,Poids_chantiers/2,IF(P14>=Chantiers_plein_poids_des,Poids_chantiers,Poids_chantiers*(0.5+0.5*(LN(P14)-LN(Chantiers_demi_poids_sous))/(LN(Chantiers_plein_poids_des)-LN(Chantiers_demi_poids_sous))))) | S14: =Q14*Poids_carte | T14: =Q14*Poids_travaux | U14: =Q14*R14 | V14: =Q14*Poids_participer | W14: =Q14*Poids_diagnostic | X14: =SUM(S14:W14) | Y14: =5 | Z14: =MIN(0.9,MAX(0,Y14-1)*Remise_par_module_ajoute) | AA14: =MAX(S14:W14)*Z14 | AB14: =X14-AA14 | AC14: =IFERROR(VLOOKUP('Grille'!$C$5,Table_engagements,4,FALSE),0) | AD14: =AB14*AC14 | AE14: =AB14-AD14 | AF14: =AE14*12 | AG14: =IF(P14<Mise_en_service_offerte_sous,0,AE14*Mise_en_service_mois) | AH14: =AG14+AF14*IF(N('Grille'!$C$5)>0,'Grille'!$C$5,1) | AI14: =IF(AH14>=Seuil_3,"Procédure formalisée",IF(AH14>=Seuil_2,"Publicité obligatoire",IF(AH14>=Seuil_1,"Procédure adaptée","Sous les seuils"))) | AJ14: =IF(AE14<1000,10,IF(AE14<10000,100,IF(AE14<100000,1000,10000))) | AK14: =FLOOR(AE14*(1-Fourchette_marge),AJ14) | AL14: =CEILING(AE14*(1+Fourchette_marge),AJ14) | AM14: =IF(AH14<1000,10,IF(AH14<10000,100,IF(AH14<100000,1000,10000))) | AN14: =FLOOR(AH14*(1-Fourchette_marge),AM14) | AO14: =CEILING(AH14*(1+Fourchette_marge),AM14)
B15: 20000 | C15: =Q15 | D15: =S15*(1-AC15) | E15: =T15*(1-AC15) | F15: =U15*(1-AC15) | G15: =V15*(1-AC15) | H15: =W15*(1-AC15) | I15: =AE15 | J15: =AG15 | K15: =AH15 | L15: =AI15 | M15: =TRIM(TEXT(AK15,"# ##0"))&" à "&TRIM(TEXT(AL15,"# ##0"))&" €" | P15: =MIN(Population_maximum,MAX(Population_minimum,ROUND($B15,0))) | Q15: =Prix_ancre*(P15/Population_ancre)^Exposant | R15: =IF(P15<=Chantiers_demi_poids_sous,Poids_chantiers/2,IF(P15>=Chantiers_plein_poids_des,Poids_chantiers,Poids_chantiers*(0.5+0.5*(LN(P15)-LN(Chantiers_demi_poids_sous))/(LN(Chantiers_plein_poids_des)-LN(Chantiers_demi_poids_sous))))) | S15: =Q15*Poids_carte | T15: =Q15*Poids_travaux | U15: =Q15*R15 | V15: =Q15*Poids_participer | W15: =Q15*Poids_diagnostic | X15: =SUM(S15:W15) | Y15: =5 | Z15: =MIN(0.9,MAX(0,Y15-1)*Remise_par_module_ajoute) | AA15: =MAX(S15:W15)*Z15 | AB15: =X15-AA15 | AC15: =IFERROR(VLOOKUP('Grille'!$C$5,Table_engagements,4,FALSE),0) | AD15: =AB15*AC15 | AE15: =AB15-AD15 | AF15: =AE15*12 | AG15: =IF(P15<Mise_en_service_offerte_sous,0,AE15*Mise_en_service_mois) | AH15: =AG15+AF15*IF(N('Grille'!$C$5)>0,'Grille'!$C$5,1) | AI15: =IF(AH15>=Seuil_3,"Procédure formalisée",IF(AH15>=Seuil_2,"Publicité obligatoire",IF(AH15>=Seuil_1,"Procédure adaptée","Sous les seuils"))) | AJ15: =IF(AE15<1000,10,IF(AE15<10000,100,IF(AE15<100000,1000,10000))) | AK15: =FLOOR(AE15*(1-Fourchette_marge),AJ15) | AL15: =CEILING(AE15*(1+Fourchette_marge),AJ15) | AM15: =IF(AH15<1000,10,IF(AH15<10000,100,IF(AH15<100000,1000,10000))) | AN15: =FLOOR(AH15*(1-Fourchette_marge),AM15) | AO15: =CEILING(AH15*(1+Fourchette_marge),AM15)
B16: 35000 | C16: =Q16 | D16: =S16*(1-AC16) | E16: =T16*(1-AC16) | F16: =U16*(1-AC16) | G16: =V16*(1-AC16) | H16: =W16*(1-AC16) | I16: =AE16 | J16: =AG16 | K16: =AH16 | L16: =AI16 | M16: =TRIM(TEXT(AK16,"# ##0"))&" à "&TRIM(TEXT(AL16,"# ##0"))&" €" | P16: =MIN(Population_maximum,MAX(Population_minimum,ROUND($B16,0))) | Q16: =Prix_ancre*(P16/Population_ancre)^Exposant | R16: =IF(P16<=Chantiers_demi_poids_sous,Poids_chantiers/2,IF(P16>=Chantiers_plein_poids_des,Poids_chantiers,Poids_chantiers*(0.5+0.5*(LN(P16)-LN(Chantiers_demi_poids_sous))/(LN(Chantiers_plein_poids_des)-LN(Chantiers_demi_poids_sous))))) | S16: =Q16*Poids_carte | T16: =Q16*Poids_travaux | U16: =Q16*R16 | V16: =Q16*Poids_participer | W16: =Q16*Poids_diagnostic | X16: =SUM(S16:W16) | Y16: =5 | Z16: =MIN(0.9,MAX(0,Y16-1)*Remise_par_module_ajoute) | AA16: =MAX(S16:W16)*Z16 | AB16: =X16-AA16 | AC16: =IFERROR(VLOOKUP('Grille'!$C$5,Table_engagements,4,FALSE),0) | AD16: =AB16*AC16 | AE16: =AB16-AD16 | AF16: =AE16*12 | AG16: =IF(P16<Mise_en_service_offerte_sous,0,AE16*Mise_en_service_mois) | AH16: =AG16+AF16*IF(N('Grille'!$C$5)>0,'Grille'!$C$5,1) | AI16: =IF(AH16>=Seuil_3,"Procédure formalisée",IF(AH16>=Seuil_2,"Publicité obligatoire",IF(AH16>=Seuil_1,"Procédure adaptée","Sous les seuils"))) | AJ16: =IF(AE16<1000,10,IF(AE16<10000,100,IF(AE16<100000,1000,10000))) | AK16: =FLOOR(AE16*(1-Fourchette_marge),AJ16) | AL16: =CEILING(AE16*(1+Fourchette_marge),AJ16) | AM16: =IF(AH16<1000,10,IF(AH16<10000,100,IF(AH16<100000,1000,10000))) | AN16: =FLOOR(AH16*(1-Fourchette_marge),AM16) | AO16: =CEILING(AH16*(1+Fourchette_marge),AM16)
B17: 50000 | C17: =Q17 | D17: =S17*(1-AC17) | E17: =T17*(1-AC17) | F17: =U17*(1-AC17) | G17: =V17*(1-AC17) | H17: =W17*(1-AC17) | I17: =AE17 | J17: =AG17 | K17: =AH17 | L17: =AI17 | M17: =TRIM(TEXT(AK17,"# ##0"))&" à "&TRIM(TEXT(AL17,"# ##0"))&" €" | P17: =MIN(Population_maximum,MAX(Population_minimum,ROUND($B17,0))) | Q17: =Prix_ancre*(P17/Population_ancre)^Exposant | R17: =IF(P17<=Chantiers_demi_poids_sous,Poids_chantiers/2,IF(P17>=Chantiers_plein_poids_des,Poids_chantiers,Poids_chantiers*(0.5+0.5*(LN(P17)-LN(Chantiers_demi_poids_sous))/(LN(Chantiers_plein_poids_des)-LN(Chantiers_demi_poids_sous))))) | S17: =Q17*Poids_carte | T17: =Q17*Poids_travaux | U17: =Q17*R17 | V17: =Q17*Poids_participer | W17: =Q17*Poids_diagnostic | X17: =SUM(S17:W17) | Y17: =5 | Z17: =MIN(0.9,MAX(0,Y17-1)*Remise_par_module_ajoute) | AA17: =MAX(S17:W17)*Z17 | AB17: =X17-AA17 | AC17: =IFERROR(VLOOKUP('Grille'!$C$5,Table_engagements,4,FALSE),0) | AD17: =AB17*AC17 | AE17: =AB17-AD17 | AF17: =AE17*12 | AG17: =IF(P17<Mise_en_service_offerte_sous,0,AE17*Mise_en_service_mois) | AH17: =AG17+AF17*IF(N('Grille'!$C$5)>0,'Grille'!$C$5,1) | AI17: =IF(AH17>=Seuil_3,"Procédure formalisée",IF(AH17>=Seuil_2,"Publicité obligatoire",IF(AH17>=Seuil_1,"Procédure adaptée","Sous les seuils"))) | AJ17: =IF(AE17<1000,10,IF(AE17<10000,100,IF(AE17<100000,1000,10000))) | AK17: =FLOOR(AE17*(1-Fourchette_marge),AJ17) | AL17: =CEILING(AE17*(1+Fourchette_marge),AJ17) | AM17: =IF(AH17<1000,10,IF(AH17<10000,100,IF(AH17<100000,1000,10000))) | AN17: =FLOOR(AH17*(1-Fourchette_marge),AM17) | AO17: =CEILING(AH17*(1+Fourchette_marge),AM17)
B18: 80000 | C18: =Q18 | D18: =S18*(1-AC18) | E18: =T18*(1-AC18) | F18: =U18*(1-AC18) | G18: =V18*(1-AC18) | H18: =W18*(1-AC18) | I18: =AE18 | J18: =AG18 | K18: =AH18 | L18: =AI18 | M18: =TRIM(TEXT(AK18,"# ##0"))&" à "&TRIM(TEXT(AL18,"# ##0"))&" €" | P18: =MIN(Population_maximum,MAX(Population_minimum,ROUND($B18,0))) | Q18: =Prix_ancre*(P18/Population_ancre)^Exposant | R18: =IF(P18<=Chantiers_demi_poids_sous,Poids_chantiers/2,IF(P18>=Chantiers_plein_poids_des,Poids_chantiers,Poids_chantiers*(0.5+0.5*(LN(P18)-LN(Chantiers_demi_poids_sous))/(LN(Chantiers_plein_poids_des)-LN(Chantiers_demi_poids_sous))))) | S18: =Q18*Poids_carte | T18: =Q18*Poids_travaux | U18: =Q18*R18 | V18: =Q18*Poids_participer | W18: =Q18*Poids_diagnostic | X18: =SUM(S18:W18) | Y18: =5 | Z18: =MIN(0.9,MAX(0,Y18-1)*Remise_par_module_ajoute) | AA18: =MAX(S18:W18)*Z18 | AB18: =X18-AA18 | AC18: =IFERROR(VLOOKUP('Grille'!$C$5,Table_engagements,4,FALSE),0) | AD18: =AB18*AC18 | AE18: =AB18-AD18 | AF18: =AE18*12 | AG18: =IF(P18<Mise_en_service_offerte_sous,0,AE18*Mise_en_service_mois) | AH18: =AG18+AF18*IF(N('Grille'!$C$5)>0,'Grille'!$C$5,1) | AI18: =IF(AH18>=Seuil_3,"Procédure formalisée",IF(AH18>=Seuil_2,"Publicité obligatoire",IF(AH18>=Seuil_1,"Procédure adaptée","Sous les seuils"))) | AJ18: =IF(AE18<1000,10,IF(AE18<10000,100,IF(AE18<100000,1000,10000))) | AK18: =FLOOR(AE18*(1-Fourchette_marge),AJ18) | AL18: =CEILING(AE18*(1+Fourchette_marge),AJ18) | AM18: =IF(AH18<1000,10,IF(AH18<10000,100,IF(AH18<100000,1000,10000))) | AN18: =FLOOR(AH18*(1-Fourchette_marge),AM18) | AO18: =CEILING(AH18*(1+Fourchette_marge),AM18)
B19: 150000 | C19: =Q19 | D19: =S19*(1-AC19) | E19: =T19*(1-AC19) | F19: =U19*(1-AC19) | G19: =V19*(1-AC19) | H19: =W19*(1-AC19) | I19: =AE19 | J19: =AG19 | K19: =AH19 | L19: =AI19 | M19: =TRIM(TEXT(AK19,"# ##0"))&" à "&TRIM(TEXT(AL19,"# ##0"))&" €" | P19: =MIN(Population_maximum,MAX(Population_minimum,ROUND($B19,0))) | Q19: =Prix_ancre*(P19/Population_ancre)^Exposant | R19: =IF(P19<=Chantiers_demi_poids_sous,Poids_chantiers/2,IF(P19>=Chantiers_plein_poids_des,Poids_chantiers,Poids_chantiers*(0.5+0.5*(LN(P19)-LN(Chantiers_demi_poids_sous))/(LN(Chantiers_plein_poids_des)-LN(Chantiers_demi_poids_sous))))) | S19: =Q19*Poids_carte | T19: =Q19*Poids_travaux | U19: =Q19*R19 | V19: =Q19*Poids_participer | W19: =Q19*Poids_diagnostic | X19: =SUM(S19:W19) | Y19: =5 | Z19: =MIN(0.9,MAX(0,Y19-1)*Remise_par_module_ajoute) | AA19: =MAX(S19:W19)*Z19 | AB19: =X19-AA19 | AC19: =IFERROR(VLOOKUP('Grille'!$C$5,Table_engagements,4,FALSE),0) | AD19: =AB19*AC19 | AE19: =AB19-AD19 | AF19: =AE19*12 | AG19: =IF(P19<Mise_en_service_offerte_sous,0,AE19*Mise_en_service_mois) | AH19: =AG19+AF19*IF(N('Grille'!$C$5)>0,'Grille'!$C$5,1) | AI19: =IF(AH19>=Seuil_3,"Procédure formalisée",IF(AH19>=Seuil_2,"Publicité obligatoire",IF(AH19>=Seuil_1,"Procédure adaptée","Sous les seuils"))) | AJ19: =IF(AE19<1000,10,IF(AE19<10000,100,IF(AE19<100000,1000,10000))) | AK19: =FLOOR(AE19*(1-Fourchette_marge),AJ19) | AL19: =CEILING(AE19*(1+Fourchette_marge),AJ19) | AM19: =IF(AH19<1000,10,IF(AH19<10000,100,IF(AH19<100000,1000,10000))) | AN19: =FLOOR(AH19*(1-Fourchette_marge),AM19) | AO19: =CEILING(AH19*(1+Fourchette_marge),AM19)
... B22: 1000000 | C22: =Q22 | D22: =S22*(1-AC22) | E22: =T22*(1-AC22) | F22: =U22*(1-AC22) | G22: =V22*(1-AC22) | H22: =W22*(1-AC22) | I22: =AE22 | J22: =AG22 | K22: =AH22 | L22: =AI22 | M22: =TRIM(TEXT(AK22,"# ##0"))&" à "&TRIM(TEXT(AL22,"# ##0"))&" €" | P22: =MIN(Population_maximum,MAX(Population_minimum,ROUND($B22,0))) | Q22: =Prix_ancre*(P22/Population_ancre)^Exposant | R22: =IF(P22<=Chantiers_demi_poids_sous,Poids_chantiers/2,IF(P22>=Chantiers_plein_poids_des,Poids_chantiers,Poids_chantiers*(0.5+0.5*(LN(P22)-LN(Chantiers_demi_poids_sous))/(LN(Chantiers_plein_poids_des)-LN(Chantiers_demi_poids_sous))))) | S22: =Q22*Poids_carte | T22: =Q22*Poids_travaux | U22: =Q22*R22 | V22: =Q22*Poids_participer | W22: =Q22*Poids_diagnostic | X22: =SUM(S22:W22) | Y22: =5 | Z22: =MIN(0.9,MAX(0,Y22-1)*Remise_par_module_ajoute) | AA22: =MAX(S22:W22)*Z22 | AB22: =X22-AA22 | AC22: =IFERROR(VLOOKUP('Grille'!$C$5,Table_engagements,4,FALSE),0) | AD22: =AB22*AC22 | AE22: =AB22-AD22 | AF22: =AE22*12 | AG22: =IF(P22<Mise_en_service_offerte_sous,0,AE22*Mise_en_service_mois) | AH22: =AG22+AF22*IF(N('Grille'!$C$5)>0,'Grille'!$C$5,1) | AI22: =IF(AH22>=Seuil_3,"Procédure formalisée",IF(AH22>=Seuil_2,"Publicité obligatoire",IF(AH22>=Seuil_1,"Procédure adaptée","Sous les seuils"))) | AJ22: =IF(AE22<1000,10,IF(AE22<10000,100,IF(AE22<100000,1000,10000))) | AK22: =FLOOR(AE22*(1-Fourchette_marge),AJ22) | AL22: =CEILING(AE22*(1+Fourchette_marge),AJ22) | AM22: =IF(AH22<1000,10,IF(AH22<10000,100,IF(AH22<100000,1000,10000))) | AN22: =FLOOR(AH22*(1-Fourchette_marge),AM22) | AO22: =CEILING(AH22*(1+Fourchette_marge),AM22)

Sheet Scénarios
B2: Vos scénarios
B3: Une ligne par cas : un nom, la population, Oui ou Non pour chaque module, la durée d'engagement. Le prix se calcule tout seul, avec la fourchette que le visiteur verrait sur le site. Les exemples se remplacent.
B5: Scénario | C5: Habitants | D5: Carte des projets urbains | E5: Travaux du quotidien | F5: Chantiers et arrêtés | G5: Signalement | H5: Diagnostic terrain | I5: Engagement (années) | J5: Mensuel HT | K5: Annuel HT | L5: Mise en service | M5: Total sur la durée | N5: Seuil dépassé | O5: Fourchette publique, par mois | P5: Fourchette publique, total | R5: Population retenue | S5: Prix d'une unité de poids | T5: Poids chantiers | U5: Prix Carte des projets urbains | V5: Prix Travaux du quotidien | W5: Prix Chantiers et arrêtés | X5: Prix Signalement | Y5: Prix Diagnostic terrain | Z5: Total avant remises | AA5: Modules retenus | AB5: Taux remise multi-modules | AC5: Remise multi-modules | AD5: Après remise multi-modules | AE5: Taux engagement | AF5: Remise engagement | AG5: Mensuel | AH5: Annuel | AI5: Mise en service | AJ5: Total sur la durée | AK5: Seuil | AL5: Pas d'arrondi (mensuel) | AM5: Fourchette basse (mensuel) | AN5: Fourchette haute (mensuel) | AO5: Pas d'arrondi (total) | AP5: Fourchette basse (total) | AQ5: Fourchette haute (total)
B6: Village, la carte seule | C6: 800 | D6: Oui | E6: Non | F6: Non | G6: Non | H6: Non | I6: 3 | J6: =IF($C6="","",AG6) | K6: =IF($C6="","",AH6) | L6: =IF($C6="","",AI6) | M6: =IF($C6="","",AJ6) | N6: =IF($C6="","",AK6) | O6: =IF($C6="","",TRIM(TEXT(AM6,"# ##0"))&" à "&TRIM(TEXT(AN6,"# ##0"))&" €") | P6: =IF($C6="","",TRIM(TEXT(AP6,"# ##0"))&" à "&TRIM(TEXT(AQ6,"# ##0"))&" €") | R6: =MIN(Population_maximum,MAX(Population_minimum,ROUND($C6,0))) | S6: =Prix_ancre*(R6/Population_ancre)^Exposant | T6: =IF(R6<=Chantiers_demi_poids_sous,Poids_chantiers/2,IF(R6>=Chantiers_plein_poids_des,Poids_chantiers,Poids_chantiers*(0.5+0.5*(LN(R6)-LN(Chantiers_demi_poids_sous))/(LN(Chantiers_plein_poids_des)-LN(Chantiers_demi_poids_sous))))) | U6: =IF($D6="Oui",S6*Poids_carte,0) | V6: =IF($E6="Oui",S6*Poids_travaux,0) | W6: =IF($F6="Oui",S6*T6,0) | X6: =IF($G6="Oui",S6*Poids_participer,0) | Y6: =IF($H6="Oui",S6*Poids_diagnostic,0) | Z6: =SUM(U6:Y6) | AA6: =COUNTIF($D6:$H6,"Oui") | AB6: =MIN(0.9,MAX(0,AA6-1)*Remise_par_module_ajoute) | AC6: =MAX(U6:Y6)*AB6 | AD6: =Z6-AC6 | AE6: =IFERROR(VLOOKUP($I6,Table_engagements,4,FALSE),0) | AF6: =AD6*AE6 | AG6: =AD6-AF6 | AH6: =AG6*12 | AI6: =IF(R6<Mise_en_service_offerte_sous,0,AG6*Mise_en_service_mois) | AJ6: =AI6+AH6*IF(N($I6)>0,$I6,1) | AK6: =IF(AJ6>=Seuil_3,"Procédure formalisée",IF(AJ6>=Seuil_2,"Publicité obligatoire",IF(AJ6>=Seuil_1,"Procédure adaptée","Sous les seuils"))) | AL6: =IF(AG6<1000,10,IF(AG6<10000,100,IF(AG6<100000,1000,10000))) | AM6: =FLOOR(AG6*(1-Fourchette_marge),AL6) | AN6: =CEILING(AG6*(1+Fourchette_marge),AL6) | AO6: =IF(AJ6<1000,10,IF(AJ6<10000,100,IF(AJ6<100000,1000,10000))) | AP6: =FLOOR(AJ6*(1-Fourchette_marge),AO6) | AQ6: =CEILING(AJ6*(1+Fourchette_marge),AO6)
B7: Bourg, carte et travaux | C7: 3000 | D7: Oui | E7: Oui | F7: Non | G7: Non | H7: Non | I7: 3 | J7: =IF($C7="","",AG7) | K7: =IF($C7="","",AH7) | L7: =IF($C7="","",AI7) | M7: =IF($C7="","",AJ7) | N7: =IF($C7="","",AK7) | O7: =IF($C7="","",TRIM(TEXT(AM7,"# ##0"))&" à "&TRIM(TEXT(AN7,"# ##0"))&" €") | P7: =IF($C7="","",TRIM(TEXT(AP7,"# ##0"))&" à "&TRIM(TEXT(AQ7,"# ##0"))&" €") | R7: =MIN(Population_maximum,MAX(Population_minimum,ROUND($C7,0))) | S7: =Prix_ancre*(R7/Population_ancre)^Exposant | T7: =IF(R7<=Chantiers_demi_poids_sous,Poids_chantiers/2,IF(R7>=Chantiers_plein_poids_des,Poids_chantiers,Poids_chantiers*(0.5+0.5*(LN(R7)-LN(Chantiers_demi_poids_sous))/(LN(Chantiers_plein_poids_des)-LN(Chantiers_demi_poids_sous))))) | U7: =IF($D7="Oui",S7*Poids_carte,0) | V7: =IF($E7="Oui",S7*Poids_travaux,0) | W7: =IF($F7="Oui",S7*T7,0) | X7: =IF($G7="Oui",S7*Poids_participer,0) | Y7: =IF($H7="Oui",S7*Poids_diagnostic,0) | Z7: =SUM(U7:Y7) | AA7: =COUNTIF($D7:$H7,"Oui") | AB7: =MIN(0.9,MAX(0,AA7-1)*Remise_par_module_ajoute) | AC7: =MAX(U7:Y7)*AB7 | AD7: =Z7-AC7 | AE7: =IFERROR(VLOOKUP($I7,Table_engagements,4,FALSE),0) | AF7: =AD7*AE7 | AG7: =AD7-AF7 | AH7: =AG7*12 | AI7: =IF(R7<Mise_en_service_offerte_sous,0,AG7*Mise_en_service_mois) | AJ7: =AI7+AH7*IF(N($I7)>0,$I7,1) | AK7: =IF(AJ7>=Seuil_3,"Procédure formalisée",IF(AJ7>=Seuil_2,"Publicité obligatoire",IF(AJ7>=Seuil_1,"Procédure adaptée","Sous les seuils"))) | AL7: =IF(AG7<1000,10,IF(AG7<10000,100,IF(AG7<100000,1000,10000))) | AM7: =FLOOR(AG7*(1-Fourchette_marge),AL7) | AN7: =CEILING(AG7*(1+Fourchette_marge),AL7) | AO7: =IF(AJ7<1000,10,IF(AJ7<10000,100,IF(AJ7<100000,1000,10000))) | AP7: =FLOOR(AJ7*(1-Fourchette_marge),AO7) | AQ7: =CEILING(AJ7*(1+Fourchette_marge),AO7)
B8: Bourg, chantiers seul | C8: 3000 | D8: Non | E8: Non | F8: Oui | G8: Non | H8: Non | I8: 1 | J8: =IF($C8="","",AG8) | K8: =IF($C8="","",AH8) | L8: =IF($C8="","",AI8) | M8: =IF($C8="","",AJ8) | N8: =IF($C8="","",AK8) | O8: =IF($C8="","",TRIM(TEXT(AM8,"# ##0"))&" à "&TRIM(TEXT(AN8,"# ##0"))&" €") | P8: =IF($C8="","",TRIM(TEXT(AP8,"# ##0"))&" à "&TRIM(TEXT(AQ8,"# ##0"))&" €") | R8: =MIN(Population_maximum,MAX(Population_minimum,ROUND($C8,0))) | S8: =Prix_ancre*(R8/Population_ancre)^Exposant | T8: =IF(R8<=Chantiers_demi_poids_sous,Poids_chantiers/2,IF(R8>=Chantiers_plein_poids_des,Poids_chantiers,Poids_chantiers*(0.5+0.5*(LN(R8)-LN(Chantiers_demi_poids_sous))/(LN(Chantiers_plein_poids_des)-LN(Chantiers_demi_poids_sous))))) | U8: =IF($D8="Oui",S8*Poids_carte,0) | V8: =IF($E8="Oui",S8*Poids_travaux,0) | W8: =IF($F8="Oui",S8*T8,0) | X8: =IF($G8="Oui",S8*Poids_participer,0) | Y8: =IF($H8="Oui",S8*Poids_diagnostic,0) | Z8: =SUM(U8:Y8) | AA8: =COUNTIF($D8:$H8,"Oui") | AB8: =MIN(0.9,MAX(0,AA8-1)*Remise_par_module_ajoute) | AC8: =MAX(U8:Y8)*AB8 | AD8: =Z8-AC8 | AE8: =IFERROR(VLOOKUP($I8,Table_engagements,4,FALSE),0) | AF8: =AD8*AE8 | AG8: =AD8-AF8 | AH8: =AG8*12 | AI8: =IF(R8<Mise_en_service_offerte_sous,0,AG8*Mise_en_service_mois) | AJ8: =AI8+AH8*IF(N($I8)>0,$I8,1) | AK8: =IF(AJ8>=Seuil_3,"Procédure formalisée",IF(AJ8>=Seuil_2,"Publicité obligatoire",IF(AJ8>=Seuil_1,"Procédure adaptée","Sous les seuils"))) | AL8: =IF(AG8<1000,10,IF(AG8<10000,100,IF(AG8<100000,1000,10000))) | AM8: =FLOOR(AG8*(1-Fourchette_marge),AL8) | AN8: =CEILING(AG8*(1+Fourchette_marge),AL8) | AO8: =IF(AJ8<1000,10,IF(AJ8<10000,100,IF(AJ8<100000,1000,10000))) | AP8: =FLOOR(AJ8*(1-Fourchette_marge),AO8) | AQ8: =CEILING(AJ8*(1+Fourchette_marge),AO8)
B9: Petite ville, carte, travaux et signalement | C9: 12000 | D9: Oui | E9: Oui | F9: Non | G9: Oui | H9: Non | I9: 3 | J9: =IF($C9="","",AG9) | K9: =IF($C9="","",AH9) | L9: =IF($C9="","",AI9) | M9: =IF($C9="","",AJ9) | N9: =IF($C9="","",AK9) | O9: =IF($C9="","",TRIM(TEXT(AM9,"# ##0"))&" à "&TRIM(TEXT(AN9,"# ##0"))&" €") | P9: =IF($C9="","",TRIM(TEXT(AP9,"# ##0"))&" à "&TRIM(TEXT(AQ9,"# ##0"))&" €") | R9: =MIN(Population_maximum,MAX(Population_minimum,ROUND($C9,0))) | S9: =Prix_ancre*(R9/Population_ancre)^Exposant | T9: =IF(R9<=Chantiers_demi_poids_sous,Poids_chantiers/2,IF(R9>=Chantiers_plein_poids_des,Poids_chantiers,Poids_chantiers*(0.5+0.5*(LN(R9)-LN(Chantiers_demi_poids_sous))/(LN(Chantiers_plein_poids_des)-LN(Chantiers_demi_poids_sous))))) | U9: =IF($D9="Oui",S9*Poids_carte,0) | V9: =IF($E9="Oui",S9*Poids_travaux,0) | W9: =IF($F9="Oui",S9*T9,0) | X9: =IF($G9="Oui",S9*Poids_participer,0) | Y9: =IF($H9="Oui",S9*Poids_diagnostic,0) | Z9: =SUM(U9:Y9) | AA9: =COUNTIF($D9:$H9,"Oui") | AB9: =MIN(0.9,MAX(0,AA9-1)*Remise_par_module_ajoute) | AC9: =MAX(U9:Y9)*AB9 | AD9: =Z9-AC9 | AE9: =IFERROR(VLOOKUP($I9,Table_engagements,4,FALSE),0) | AF9: =AD9*AE9 | AG9: =AD9-AF9 | AH9: =AG9*12 | AI9: =IF(R9<Mise_en_service_offerte_sous,0,AG9*Mise_en_service_mois) | AJ9: =AI9+AH9*IF(N($I9)>0,$I9,1) | AK9: =IF(AJ9>=Seuil_3,"Procédure formalisée",IF(AJ9>=Seuil_2,"Publicité obligatoire",IF(AJ9>=Seuil_1,"Procédure adaptée","Sous les seuils"))) | AL9: =IF(AG9<1000,10,IF(AG9<10000,100,IF(AG9<100000,1000,10000))) | AM9: =FLOOR(AG9*(1-Fourchette_marge),AL9) | AN9: =CEILING(AG9*(1+Fourchette_marge),AL9) | AO9: =IF(AJ9<1000,10,IF(AJ9<10000,100,IF(AJ9<100000,1000,10000))) | AP9: =FLOOR(AJ9*(1-Fourchette_marge),AO9) | AQ9: =CEILING(AJ9*(1+Fourchette_marge),AO9)
B10: Petite ville, la suite complète | C10: 12000 | D10: Oui | E10: Oui | F10: Oui | G10: Oui | H10: Oui | I10: 4 | J10: =IF($C10="","",AG10) | K10: =IF($C10="","",AH10) | L10: =IF($C10="","",AI10) | M10: =IF($C10="","",AJ10) | N10: =IF($C10="","",AK10) | O10: =IF($C10="","",TRIM(TEXT(AM10,"# ##0"))&" à "&TRIM(TEXT(AN10,"# ##0"))&" €") | P10: =IF($C10="","",TRIM(TEXT(AP10,"# ##0"))&" à "&TRIM(TEXT(AQ10,"# ##0"))&" €") | R10: =MIN(Population_maximum,MAX(Population_minimum,ROUND($C10,0))) | S10: =Prix_ancre*(R10/Population_ancre)^Exposant | T10: =IF(R10<=Chantiers_demi_poids_sous,Poids_chantiers/2,IF(R10>=Chantiers_plein_poids_des,Poids_chantiers,Poids_chantiers*(0.5+0.5*(LN(R10)-LN(Chantiers_demi_poids_sous))/(LN(Chantiers_plein_poids_des)-LN(Chantiers_demi_poids_sous))))) | U10: =IF($D10="Oui",S10*Poids_carte,0) | V10: =IF($E10="Oui",S10*Poids_travaux,0) | W10: =IF($F10="Oui",S10*T10,0) | X10: =IF($G10="Oui",S10*Poids_participer,0) | Y10: =IF($H10="Oui",S10*Poids_diagnostic,0) | Z10: =SUM(U10:Y10) | AA10: =COUNTIF($D10:$H10,"Oui") | AB10: =MIN(0.9,MAX(0,AA10-1)*Remise_par_module_ajoute) | AC10: =MAX(U10:Y10)*AB10 | AD10: =Z10-AC10 | AE10: =IFERROR(VLOOKUP($I10,Table_engagements,4,FALSE),0) | AF10: =AD10*AE10 | AG10: =AD10-AF10 | AH10: =AG10*12 | AI10: =IF(R10<Mise_en_service_offerte_sous,0,AG10*Mise_en_service_mois) | AJ10: =AI10+AH10*IF(N($I10)>0,$I10,1) | AK10: =IF(AJ10>=Seuil_3,"Procédure formalisée",IF(AJ10>=Seuil_2,"Publicité obligatoire",IF(AJ10>=Seuil_1,"Procédure adaptée","Sous les seuils"))) | AL10: =IF(AG10<1000,10,IF(AG10<10000,100,IF(AG10<100000,1000,10000))) | AM10: =FLOOR(AG10*(1-Fourchette_marge),AL10) | AN10: =CEILING(AG10*(1+Fourchette_marge),AL10) | AO10: =IF(AJ10<1000,10,IF(AJ10<10000,100,IF(AJ10<100000,1000,10000))) | AP10: =FLOOR(AJ10*(1-Fourchette_marge),AO10) | AQ10: =CEILING(AJ10*(1+Fourchette_marge),AO10)
B11: Ville moyenne, carte et signalement | C11: 50000 | D11: Oui | E11: Non | F11: Non | G11: Oui | H11: Non | I11: 2 | J11: =IF($C11="","",AG11) | K11: =IF($C11="","",AH11) | L11: =IF($C11="","",AI11) | M11: =IF($C11="","",AJ11) | N11: =IF($C11="","",AK11) | O11: =IF($C11="","",TRIM(TEXT(AM11,"# ##0"))&" à "&TRIM(TEXT(AN11,"# ##0"))&" €") | P11: =IF($C11="","",TRIM(TEXT(AP11,"# ##0"))&" à "&TRIM(TEXT(AQ11,"# ##0"))&" €") | R11: =MIN(Population_maximum,MAX(Population_minimum,ROUND($C11,0))) | S11: =Prix_ancre*(R11/Population_ancre)^Exposant | T11: =IF(R11<=Chantiers_demi_poids_sous,Poids_chantiers/2,IF(R11>=Chantiers_plein_poids_des,Poids_chantiers,Poids_chantiers*(0.5+0.5*(LN(R11)-LN(Chantiers_demi_poids_sous))/(LN(Chantiers_plein_poids_des)-LN(Chantiers_demi_poids_sous))))) | U11: =IF($D11="Oui",S11*Poids_carte,0) | V11: =IF($E11="Oui",S11*Poids_travaux,0) | W11: =IF($F11="Oui",S11*T11,0) | X11: =IF($G11="Oui",S11*Poids_participer,0) | Y11: =IF($H11="Oui",S11*Poids_diagnostic,0) | Z11: =SUM(U11:Y11) | AA11: =COUNTIF($D11:$H11,"Oui") | AB11: =MIN(0.9,MAX(0,AA11-1)*Remise_par_module_ajoute) | AC11: =MAX(U11:Y11)*AB11 | AD11: =Z11-AC11 | AE11: =IFERROR(VLOOKUP($I11,Table_engagements,4,FALSE),0) | AF11: =AD11*AE11 | AG11: =AD11-AF11 | AH11: =AG11*12 | AI11: =IF(R11<Mise_en_service_offerte_sous,0,AG11*Mise_en_service_mois) | AJ11: =AI11+AH11*IF(N($I11)>0,$I11,1) | AK11: =IF(AJ11>=Seuil_3,"Procédure formalisée",IF(AJ11>=Seuil_2,"Publicité obligatoire",IF(AJ11>=Seuil_1,"Procédure adaptée","Sous les seuils"))) | AL11: =IF(AG11<1000,10,IF(AG11<10000,100,IF(AG11<100000,1000,10000))) | AM11: =FLOOR(AG11*(1-Fourchette_marge),AL11) | AN11: =CEILING(AG11*(1+Fourchette_marge),AL11) | AO11: =IF(AJ11<1000,10,IF(AJ11<10000,100,IF(AJ11<100000,1000,10000))) | AP11: =FLOOR(AJ11*(1-Fourchette_marge),AO11) | AQ11: =CEILING(AJ11*(1+Fourchette_marge),AO11)
B12: Ville moyenne, la suite complète | C12: 50000 | D12: Oui | E12: Oui | F12: Oui | G12: Oui | H12: Oui | I12: 3 | J12: =IF($C12="","",AG12) | K12: =IF($C12="","",AH12) | L12: =IF($C12="","",AI12) | M12: =IF($C12="","",AJ12) | N12: =IF($C12="","",AK12) | O12: =IF($C12="","",TRIM(TEXT(AM12,"# ##0"))&" à "&TRIM(TEXT(AN12,"# ##0"))&" €") | P12: =IF($C12="","",TRIM(TEXT(AP12,"# ##0"))&" à "&TRIM(TEXT(AQ12,"# ##0"))&" €") | R12: =MIN(Population_maximum,MAX(Population_minimum,ROUND($C12,0))) | S12: =Prix_ancre*(R12/Population_ancre)^Exposant | T12: =IF(R12<=Chantiers_demi_poids_sous,Poids_chantiers/2,IF(R12>=Chantiers_plein_poids_des,Poids_chantiers,Poids_chantiers*(0.5+0.5*(LN(R12)-LN(Chantiers_demi_poids_sous))/(LN(Chantiers_plein_poids_des)-LN(Chantiers_demi_poids_sous))))) | U12: =IF($D12="Oui",S12*Poids_carte,0) | V12: =IF($E12="Oui",S12*Poids_travaux,0) | W12: =IF($F12="Oui",S12*T12,0) | X12: =IF($G12="Oui",S12*Poids_participer,0) | Y12: =IF($H12="Oui",S12*Poids_diagnostic,0) | Z12: =SUM(U12:Y12) | AA12: =COUNTIF($D12:$H12,"Oui") | AB12: =MIN(0.9,MAX(0,AA12-1)*Remise_par_module_ajoute) | AC12: =MAX(U12:Y12)*AB12 | AD12: =Z12-AC12 | AE12: =IFERROR(VLOOKUP($I12,Table_engagements,4,FALSE),0) | AF12: =AD12*AE12 | AG12: =AD12-AF12 | AH12: =AG12*12 | AI12: =IF(R12<Mise_en_service_offerte_sous,0,AG12*Mise_en_service_mois) | AJ12: =AI12+AH12*IF(N($I12)>0,$I12,1) | AK12: =IF(AJ12>=Seuil_3,"Procédure formalisée",IF(AJ12>=Seuil_2,"Publicité obligatoire",IF(AJ12>=Seuil_1,"Procédure adaptée","Sous les seuils"))) | AL12: =IF(AG12<1000,10,IF(AG12<10000,100,IF(AG12<100000,1000,10000))) | AM12: =FLOOR(AG12*(1-Fourchette_marge),AL12) | AN12: =CEILING(AG12*(1+Fourchette_marge),AL12) | AO12: =IF(AJ12<1000,10,IF(AJ12<10000,100,IF(AJ12<100000,1000,10000))) | AP12: =FLOOR(AJ12*(1-Fourchette_marge),AO12) | AQ12: =CEILING(AJ12*(1+Fourchette_marge),AO12)
B13: Grande ville, carte et diagnostic | C13: 150000 | D13: Oui | E13: Non | F13: Non | G13: Non | H13: Oui | I13: 3 | J13: =IF($C13="","",AG13) | K13: =IF($C13="","",AH13) | L13: =IF($C13="","",AI13) | M13: =IF($C13="","",AJ13) | N13: =IF($C13="","",AK13) | O13: =IF($C13="","",TRIM(TEXT(AM13,"# ##0"))&" à "&TRIM(TEXT(AN13,"# ##0"))&" €") | P13: =IF($C13="","",TRIM(TEXT(AP13,"# ##0"))&" à "&TRIM(TEXT(AQ13,"# ##0"))&" €") | R13: =MIN(Population_maximum,MAX(Population_minimum,ROUND($C13,0))) | S13: =Prix_ancre*(R13/Population_ancre)^Exposant | T13: =IF(R13<=Chantiers_demi_poids_sous,Poids_chantiers/2,IF(R13>=Chantiers_plein_poids_des,Poids_chantiers,Poids_chantiers*(0.5+0.5*(LN(R13)-LN(Chantiers_demi_poids_sous))/(LN(Chantiers_plein_poids_des)-LN(Chantiers_demi_poids_sous))))) | U13: =IF($D13="Oui",S13*Poids_carte,0) | V13: =IF($E13="Oui",S13*Poids_travaux,0) | W13: =IF($F13="Oui",S13*T13,0) | X13: =IF($G13="Oui",S13*Poids_participer,0) | Y13: =IF($H13="Oui",S13*Poids_diagnostic,0) | Z13: =SUM(U13:Y13) | AA13: =COUNTIF($D13:$H13,"Oui") | AB13: =MIN(0.9,MAX(0,AA13-1)*Remise_par_module_ajoute) | AC13: =MAX(U13:Y13)*AB13 | AD13: =Z13-AC13 | AE13: =IFERROR(VLOOKUP($I13,Table_engagements,4,FALSE),0) | AF13: =AD13*AE13 | AG13: =AD13-AF13 | AH13: =AG13*12 | AI13: =IF(R13<Mise_en_service_offerte_sous,0,AG13*Mise_en_service_mois) | AJ13: =AI13+AH13*IF(N($I13)>0,$I13,1) | AK13: =IF(AJ13>=Seuil_3,"Procédure formalisée",IF(AJ13>=Seuil_2,"Publicité obligatoire",IF(AJ13>=Seuil_1,"Procédure adaptée","Sous les seuils"))) | AL13: =IF(AG13<1000,10,IF(AG13<10000,100,IF(AG13<100000,1000,10000))) | AM13: =FLOOR(AG13*(1-Fourchette_marge),AL13) | AN13: =CEILING(AG13*(1+Fourchette_marge),AL13) | AO13: =IF(AJ13<1000,10,IF(AJ13<10000,100,IF(AJ13<100000,1000,10000))) | AP13: =FLOOR(AJ13*(1-Fourchette_marge),AO13) | AQ13: =CEILING(AJ13*(1+Fourchette_marge),AO13)
B14: Métropole, la carte seule | C14: 500000 | D14: Oui | E14: Non | F14: Non | G14: Non | H14: Non | I14: 4 | J14: =IF($C14="","",AG14) | K14: =IF($C14="","",AH14) | L14: =IF($C14="","",AI14) | M14: =IF($C14="","",AJ14) | N14: =IF($C14="","",AK14) | O14: =IF($C14="","",TRIM(TEXT(AM14,"# ##0"))&" à "&TRIM(TEXT(AN14,"# ##0"))&" €") | P14: =IF($C14="","",TRIM(TEXT(AP14,"# ##0"))&" à "&TRIM(TEXT(AQ14,"# ##0"))&" €") | R14: =MIN(Population_maximum,MAX(Population_minimum,ROUND($C14,0))) | S14: =Prix_ancre*(R14/Population_ancre)^Exposant | T14: =IF(R14<=Chantiers_demi_poids_sous,Poids_chantiers/2,IF(R14>=Chantiers_plein_poids_des,Poids_chantiers,Poids_chantiers*(0.5+0.5*(LN(R14)-LN(Chantiers_demi_poids_sous))/(LN(Chantiers_plein_poids_des)-LN(Chantiers_demi_poids_sous))))) | U14: =IF($D14="Oui",S14*Poids_carte,0) | V14: =IF($E14="Oui",S14*Poids_travaux,0) | W14: =IF($F14="Oui",S14*T14,0) | X14: =IF($G14="Oui",S14*Poids_participer,0) | Y14: =IF($H14="Oui",S14*Poids_diagnostic,0) | Z14: =SUM(U14:Y14) | AA14: =COUNTIF($D14:$H14,"Oui") | AB14: =MIN(0.9,MAX(0,AA14-1)*Remise_par_module_ajoute) | AC14: =MAX(U14:Y14)*AB14 | AD14: =Z14-AC14 | AE14: =IFERROR(VLOOKUP($I14,Table_engagements,4,FALSE),0) | AF14: =AD14*AE14 | AG14: =AD14-AF14 | AH14: =AG14*12 | AI14: =IF(R14<Mise_en_service_offerte_sous,0,AG14*Mise_en_service_mois) | AJ14: =AI14+AH14*IF(N($I14)>0,$I14,1) | AK14: =IF(AJ14>=Seuil_3,"Procédure formalisée",IF(AJ14>=Seuil_2,"Publicité obligatoire",IF(AJ14>=Seuil_1,"Procédure adaptée","Sous les seuils"))) | AL14: =IF(AG14<1000,10,IF(AG14<10000,100,IF(AG14<100000,1000,10000))) | AM14: =FLOOR(AG14*(1-Fourchette_marge),AL14) | AN14: =CEILING(AG14*(1+Fourchette_marge),AL14) | AO14: =IF(AJ14<1000,10,IF(AJ14<10000,100,IF(AJ14<100000,1000,10000))) | AP14: =FLOOR(AJ14*(1-Fourchette_marge),AO14) | AQ14: =CEILING(AJ14*(1+Fourchette_marge),AO14)
J15: =IF($C15="","",AG15) | K15: =IF($C15="","",AH15) | L15: =IF($C15="","",AI15) | M15: =IF($C15="","",AJ15) | N15: =IF($C15="","",AK15) | O15: =IF($C15="","",TRIM(TEXT(AM15,"# ##0"))&" à "&TRIM(TEXT(AN15,"# ##0"))&" €") | P15: =IF($C15="","",TRIM(TEXT(AP15,"# ##0"))&" à "&TRIM(TEXT(AQ15,"# ##0"))&" €") | R15: =MIN(Population_maximum,MAX(Population_minimum,ROUND($C15,0))) | S15: =Prix_ancre*(R15/Population_ancre)^Exposant | T15: =IF(R15<=Chantiers_demi_poids_sous,Poids_chantiers/2,IF(R15>=Chantiers_plein_poids_des,Poids_chantiers,Poids_chantiers*(0.5+0.5*(LN(R15)-LN(Chantiers_demi_poids_sous))/(LN(Chantiers_plein_poids_des)-LN(Chantiers_demi_poids_sous))))) | U15: =IF($D15="Oui",S15*Poids_carte,0) | V15: =IF($E15="Oui",S15*Poids_travaux,0) | W15: =IF($F15="Oui",S15*T15,0) | X15: =IF($G15="Oui",S15*Poids_participer,0) | Y15: =IF($H15="Oui",S15*Poids_diagnostic,0) | Z15: =SUM(U15:Y15) | AA15: =COUNTIF($D15:$H15,"Oui") | AB15: =MIN(0.9,MAX(0,AA15-1)*Remise_par_module_ajoute) | AC15: =MAX(U15:Y15)*AB15 | AD15: =Z15-AC15 | AE15: =IFERROR(VLOOKUP($I15,Table_engagements,4,FALSE),0) | AF15: =AD15*AE15 | AG15: =AD15-AF15 | AH15: =AG15*12 | AI15: =IF(R15<Mise_en_service_offerte_sous,0,AG15*Mise_en_service_mois) | AJ15: =AI15+AH15*IF(N($I15)>0,$I15,1) | AK15: =IF(AJ15>=Seuil_3,"Procédure formalisée",IF(AJ15>=Seuil_2,"Publicité obligatoire",IF(AJ15>=Seuil_1,"Procédure adaptée","Sous les seuils"))) | AL15: =IF(AG15<1000,10,IF(AG15<10000,100,IF(AG15<100000,1000,10000))) | AM15: =FLOOR(AG15*(1-Fourchette_marge),AL15) | AN15: =CEILING(AG15*(1+Fourchette_marge),AL15) | AO15: =IF(AJ15<1000,10,IF(AJ15<10000,100,IF(AJ15<100000,1000,10000))) | AP15: =FLOOR(AJ15*(1-Fourchette_marge),AO15) | AQ15: =CEILING(AJ15*(1+Fourchette_marge),AO15)
J16: =IF($C16="","",AG16) | K16: =IF($C16="","",AH16) | L16: =IF($C16="","",AI16) | M16: =IF($C16="","",AJ16) | N16: =IF($C16="","",AK16) | O16: =IF($C16="","",TRIM(TEXT(AM16,"# ##0"))&" à "&TRIM(TEXT(AN16,"# ##0"))&" €") | P16: =IF($C16="","",TRIM(TEXT(AP16,"# ##0"))&" à "&TRIM(TEXT(AQ16,"# ##0"))&" €") | R16: =MIN(Population_maximum,MAX(Population_minimum,ROUND($C16,0))) | S16: =Prix_ancre*(R16/Population_ancre)^Exposant | T16: =IF(R16<=Chantiers_demi_poids_sous,Poids_chantiers/2,IF(R16>=Chantiers_plein_poids_des,Poids_chantiers,Poids_chantiers*(0.5+0.5*(LN(R16)-LN(Chantiers_demi_poids_sous))/(LN(Chantiers_plein_poids_des)-LN(Chantiers_demi_poids_sous))))) | U16: =IF($D16="Oui",S16*Poids_carte,0) | V16: =IF($E16="Oui",S16*Poids_travaux,0) | W16: =IF($F16="Oui",S16*T16,0) | X16: =IF($G16="Oui",S16*Poids_participer,0) | Y16: =IF($H16="Oui",S16*Poids_diagnostic,0) | Z16: =SUM(U16:Y16) | AA16: =COUNTIF($D16:$H16,"Oui") | AB16: =MIN(0.9,MAX(0,AA16-1)*Remise_par_module_ajoute) | AC16: =MAX(U16:Y16)*AB16 | AD16: =Z16-AC16 | AE16: =IFERROR(VLOOKUP($I16,Table_engagements,4,FALSE),0) | AF16: =AD16*AE16 | AG16: =AD16-AF16 | AH16: =AG16*12 | AI16: =IF(R16<Mise_en_service_offerte_sous,0,AG16*Mise_en_service_mois) | AJ16: =AI16+AH16*IF(N($I16)>0,$I16,1) | AK16: =IF(AJ16>=Seuil_3,"Procédure formalisée",IF(AJ16>=Seuil_2,"Publicité obligatoire",IF(AJ16>=Seuil_1,"Procédure adaptée","Sous les seuils"))) | AL16: =IF(AG16<1000,10,IF(AG16<10000,100,IF(AG16<100000,1000,10000))) | AM16: =FLOOR(AG16*(1-Fourchette_marge),AL16) | AN16: =CEILING(AG16*(1+Fourchette_marge),AL16) | AO16: =IF(AJ16<1000,10,IF(AJ16<10000,100,IF(AJ16<100000,1000,10000))) | AP16: =FLOOR(AJ16*(1-Fourchette_marge),AO16) | AQ16: =CEILING(AJ16*(1+Fourchette_marge),AO16)
J17: =IF($C17="","",AG17) | K17: =IF($C17="","",AH17) | L17: =IF($C17="","",AI17) | M17: =IF($C17="","",AJ17) | N17: =IF($C17="","",AK17) | O17: =IF($C17="","",TRIM(TEXT(AM17,"# ##0"))&" à "&TRIM(TEXT(AN17,"# ##0"))&" €") | P17: =IF($C17="","",TRIM(TEXT(AP17,"# ##0"))&" à "&TRIM(TEXT(AQ17,"# ##0"))&" €") | R17: =MIN(Population_maximum,MAX(Population_minimum,ROUND($C17,0))) | S17: =Prix_ancre*(R17/Population_ancre)^Exposant | T17: =IF(R17<=Chantiers_demi_poids_sous,Poids_chantiers/2,IF(R17>=Chantiers_plein_poids_des,Poids_chantiers,Poids_chantiers*(0.5+0.5*(LN(R17)-LN(Chantiers_demi_poids_sous))/(LN(Chantiers_plein_poids_des)-LN(Chantiers_demi_poids_sous))))) | U17: =IF($D17="Oui",S17*Poids_carte,0) | V17: =IF($E17="Oui",S17*Poids_travaux,0) | W17: =IF($F17="Oui",S17*T17,0) | X17: =IF($G17="Oui",S17*Poids_participer,0) | Y17: =IF($H17="Oui",S17*Poids_diagnostic,0) | Z17: =SUM(U17:Y17) | AA17: =COUNTIF($D17:$H17,"Oui") | AB17: =MIN(0.9,MAX(0,AA17-1)*Remise_par_module_ajoute) | AC17: =MAX(U17:Y17)*AB17 | AD17: =Z17-AC17 | AE17: =IFERROR(VLOOKUP($I17,Table_engagements,4,FALSE),0) | AF17: =AD17*AE17 | AG17: =AD17-AF17 | AH17: =AG17*12 | AI17: =IF(R17<Mise_en_service_offerte_sous,0,AG17*Mise_en_service_mois) | AJ17: =AI17+AH17*IF(N($I17)>0,$I17,1) | AK17: =IF(AJ17>=Seuil_3,"Procédure formalisée",IF(AJ17>=Seuil_2,"Publicité obligatoire",IF(AJ17>=Seuil_1,"Procédure adaptée","Sous les seuils"))) | AL17: =IF(AG17<1000,10,IF(AG17<10000,100,IF(AG17<100000,1000,10000))) | AM17: =FLOOR(AG17*(1-Fourchette_marge),AL17) | AN17: =CEILING(AG17*(1+Fourchette_marge),AL17) | AO17: =IF(AJ17<1000,10,IF(AJ17<10000,100,IF(AJ17<100000,1000,10000))) | AP17: =FLOOR(AJ17*(1-Fourchette_marge),AO17) | AQ17: =CEILING(AJ17*(1+Fourchette_marge),AO17)
J18: =IF($C18="","",AG18) | K18: =IF($C18="","",AH18) | L18: =IF($C18="","",AI18) | M18: =IF($C18="","",AJ18) | N18: =IF($C18="","",AK18) | O18: =IF($C18="","",TRIM(TEXT(AM18,"# ##0"))&" à "&TRIM(TEXT(AN18,"# ##0"))&" €") | P18: =IF($C18="","",TRIM(TEXT(AP18,"# ##0"))&" à "&TRIM(TEXT(AQ18,"# ##0"))&" €") | R18: =MIN(Population_maximum,MAX(Population_minimum,ROUND($C18,0))) | S18: =Prix_ancre*(R18/Population_ancre)^Exposant | T18: =IF(R18<=Chantiers_demi_poids_sous,Poids_chantiers/2,IF(R18>=Chantiers_plein_poids_des,Poids_chantiers,Poids_chantiers*(0.5+0.5*(LN(R18)-LN(Chantiers_demi_poids_sous))/(LN(Chantiers_plein_poids_des)-LN(Chantiers_demi_poids_sous))))) | U18: =IF($D18="Oui",S18*Poids_carte,0) | V18: =IF($E18="Oui",S18*Poids_travaux,0) | W18: =IF($F18="Oui",S18*T18,0) | X18: =IF($G18="Oui",S18*Poids_participer,0) | Y18: =IF($H18="Oui",S18*Poids_diagnostic,0) | Z18: =SUM(U18:Y18) | AA18: =COUNTIF($D18:$H18,"Oui") | AB18: =MIN(0.9,MAX(0,AA18-1)*Remise_par_module_ajoute) | AC18: =MAX(U18:Y18)*AB18 | AD18: =Z18-AC18 | AE18: =IFERROR(VLOOKUP($I18,Table_engagements,4,FALSE),0) | AF18: =AD18*AE18 | AG18: =AD18-AF18 | AH18: =AG18*12 | AI18: =IF(R18<Mise_en_service_offerte_sous,0,AG18*Mise_en_service_mois) | AJ18: =AI18+AH18*IF(N($I18)>0,$I18,1) | AK18: =IF(AJ18>=Seuil_3,"Procédure formalisée",IF(AJ18>=Seuil_2,"Publicité obligatoire",IF(AJ18>=Seuil_1,"Procédure adaptée","Sous les seuils"))) | AL18: =IF(AG18<1000,10,IF(AG18<10000,100,IF(AG18<100000,1000,10000))) | AM18: =FLOOR(AG18*(1-Fourchette_marge),AL18) | AN18: =CEILING(AG18*(1+Fourchette_marge),AL18) | AO18: =IF(AJ18<1000,10,IF(AJ18<10000,100,IF(AJ18<100000,1000,10000))) | AP18: =FLOOR(AJ18*(1-Fourchette_marge),AO18) | AQ18: =CEILING(AJ18*(1+Fourchette_marge),AO18)
J19: =IF($C19="","",AG19) | K19: =IF($C19="","",AH19) | L19: =IF($C19="","",AI19) | M19: =IF($C19="","",AJ19) | N19: =IF($C19="","",AK19) | O19: =IF($C19="","",TRIM(TEXT(AM19,"# ##0"))&" à "&TRIM(TEXT(AN19,"# ##0"))&" €") | P19: =IF($C19="","",TRIM(TEXT(AP19,"# ##0"))&" à "&TRIM(TEXT(AQ19,"# ##0"))&" €") | R19: =MIN(Population_maximum,MAX(Population_minimum,ROUND($C19,0))) | S19: =Prix_ancre*(R19/Population_ancre)^Exposant | T19: =IF(R19<=Chantiers_demi_poids_sous,Poids_chantiers/2,IF(R19>=Chantiers_plein_poids_des,Poids_chantiers,Poids_chantiers*(0.5+0.5*(LN(R19)-LN(Chantiers_demi_poids_sous))/(LN(Chantiers_plein_poids_des)-LN(Chantiers_demi_poids_sous))))) | U19: =IF($D19="Oui",S19*Poids_carte,0) | V19: =IF($E19="Oui",S19*Poids_travaux,0) | W19: =IF($F19="Oui",S19*T19,0) | X19: =IF($G19="Oui",S19*Poids_participer,0) | Y19: =IF($H19="Oui",S19*Poids_diagnostic,0) | Z19: =SUM(U19:Y19) | AA19: =COUNTIF($D19:$H19,"Oui") | AB19: =MIN(0.9,MAX(0,AA19-1)*Remise_par_module_ajoute) | AC19: =MAX(U19:Y19)*AB19 | AD19: =Z19-AC19 | AE19: =IFERROR(VLOOKUP($I19,Table_engagements,4,FALSE),0) | AF19: =AD19*AE19 | AG19: =AD19-AF19 | AH19: =AG19*12 | AI19: =IF(R19<Mise_en_service_offerte_sous,0,AG19*Mise_en_service_mois) | AJ19: =AI19+AH19*IF(N($I19)>0,$I19,1) | AK19: =IF(AJ19>=Seuil_3,"Procédure formalisée",IF(AJ19>=Seuil_2,"Publicité obligatoire",IF(AJ19>=Seuil_1,"Procédure adaptée","Sous les seuils"))) | AL19: =IF(AG19<1000,10,IF(AG19<10000,100,IF(AG19<100000,1000,10000))) | AM19: =FLOOR(AG19*(1-Fourchette_marge),AL19) | AN19: =CEILING(AG19*(1+Fourchette_marge),AL19) | AO19: =IF(AJ19<1000,10,IF(AJ19<10000,100,IF(AJ19<100000,1000,10000))) | AP19: =FLOOR(AJ19*(1-Fourchette_marge),AO19) | AQ19: =CEILING(AJ19*(1+Fourchette_marge),AO19)
J20: =IF($C20="","",AG20) | K20: =IF($C20="","",AH20) | L20: =IF($C20="","",AI20) | M20: =IF($C20="","",AJ20) | N20: =IF($C20="","",AK20) | O20: =IF($C20="","",TRIM(TEXT(AM20,"# ##0"))&" à "&TRIM(TEXT(AN20,"# ##0"))&" €") | P20: =IF($C20="","",TRIM(TEXT(AP20,"# ##0"))&" à "&TRIM(TEXT(AQ20,"# ##0"))&" €") | R20: =MIN(Population_maximum,MAX(Population_minimum,ROUND($C20,0))) | S20: =Prix_ancre*(R20/Population_ancre)^Exposant | T20: =IF(R20<=Chantiers_demi_poids_sous,Poids_chantiers/2,IF(R20>=Chantiers_plein_poids_des,Poids_chantiers,Poids_chantiers*(0.5+0.5*(LN(R20)-LN(Chantiers_demi_poids_sous))/(LN(Chantiers_plein_poids_des)-LN(Chantiers_demi_poids_sous))))) | U20: =IF($D20="Oui",S20*Poids_carte,0) | V20: =IF($E20="Oui",S20*Poids_travaux,0) | W20: =IF($F20="Oui",S20*T20,0) | X20: =IF($G20="Oui",S20*Poids_participer,0) | Y20: =IF($H20="Oui",S20*Poids_diagnostic,0) | Z20: =SUM(U20:Y20) | AA20: =COUNTIF($D20:$H20,"Oui") | AB20: =MIN(0.9,MAX(0,AA20-1)*Remise_par_module_ajoute) | AC20: =MAX(U20:Y20)*AB20 | AD20: =Z20-AC20 | AE20: =IFERROR(VLOOKUP($I20,Table_engagements,4,FALSE),0) | AF20: =AD20*AE20 | AG20: =AD20-AF20 | AH20: =AG20*12 | AI20: =IF(R20<Mise_en_service_offerte_sous,0,AG20*Mise_en_service_mois) | AJ20: =AI20+AH20*IF(N($I20)>0,$I20,1) | AK20: =IF(AJ20>=Seuil_3,"Procédure formalisée",IF(AJ20>=Seuil_2,"Publicité obligatoire",IF(AJ20>=Seuil_1,"Procédure adaptée","Sous les seuils"))) | AL20: =IF(AG20<1000,10,IF(AG20<10000,100,IF(AG20<100000,1000,10000))) | AM20: =FLOOR(AG20*(1-Fourchette_marge),AL20) | AN20: =CEILING(AG20*(1+Fourchette_marge),AL20) | AO20: =IF(AJ20<1000,10,IF(AJ20<10000,100,IF(AJ20<100000,1000,10000))) | AP20: =FLOOR(AJ20*(1-Fourchette_marge),AO20) | AQ20: =CEILING(AJ20*(1+Fourchette_marge),AO20)
